Workbook
Name JAIME_PEÑA_PEÑA: #REF!
Name JAIME_PEÑA_PEÑA: #REF!
Name matriz: 'Reporte (2)'!$J$34:$J$38
Name RAMIRO_ANTONIO_MONROY_VARA: #REF!
Name RAMIRO_ANTONIO_MONROY_VARA: #REF!

Sheet datos crudos
A1: Nombre | F1: Puesto | L1: Fecha: | R1: Patrón
A2: Daniel Guadarrama Mejía | F2: Ingeniero de Calibración | N2: Año | O2: Consecutivo | W2: =N27 -> 0 | X2: =$O$11 -> °C | AB2: =O27 -> 0 | AC2: =$O$11 -> °C | AG2: =P27 -> 0 | AH2: =$O$11 -> °C
A3: Brenda Torres Salazar | F3: Ingeniero de Calibración | L3: Reporte: | N3: 26 | R3: 1. 02-0G-00627 | V3: IBC | W3: Patrón | X3: Patrón Corr | AA3: IBC | AB3: Patrón | AC3: Patrón Corr | AF3: IBC | AG3: Patrón | AH3: Patrón Corr | AJ3: Codigo | AK3: Descripcion | AL3: Criticidad | AM3: Codigo_Ubicacion | AN3: Departamento_Responsable | AO3: Frecuencia
A4: Marco Antonio Esquivel Balderas | F4: Ingeniero de Calibración | L4: Realizó: | R4: 2. 02-02-03948 | U4: 1 | X4: =IF(W4="","",W4-HLOOKUP($S$1,Patrones!$B$57:$AZ$82,3,FALSE)) | Z4: 1 | AC4: =IF(AB4="","",AB4-HLOOKUP($S$1,Patrones!$B$57:$AZ$82,6,FALSE)) | AE4: 1 | AH4: =IF(AG4="","",AG4-HLOOKUP($S$1,Patrones!$B$57:$AZ$82,9,FALSE)) | AJ4: 02-02-003967 | AK4: Calibrador de procesos | AL4: Critico | AM4: Calibración | AN4: Calibracion | AO4: 12
A5: Andrés López Godínez | F5: Técnico de Calibración | L5: Código | R5: 3. 02-0G-01389 | U5: 2 | X5: =IF(W5="","",W5-HLOOKUP($S$1,Patrones!$B$57:$AZ$82,3,FALSE)) | Z5: 2 | AC5: =IF(AB5="","",AB5-HLOOKUP($S$1,Patrones!$B$57:$AZ$82,6,FALSE)) | AE5: 2 | AH5: =IF(AG5="","",AG5-HLOOKUP($S$1,Patrones!$B$57:$AZ$82,9,FALSE)) | AJ5: 02-0G-00001 | AK5: Conductímetro | AL5: Crítico | AM5: Área técnica | AN5: Mantenimiento e Ingeniería | AO5: 12
A6: Ricardo Israel Padua Téllez | F6: Supervisor de Calibración | L6: Descripción | N6: =IF(N5="","",VLOOKUP($N$5,$AJ$3:$AO$2190,2,FALSE)) | R6: 4. 02-0G-00955 | U6: 3 | X6: =IF(W6="","",W6-HLOOKUP($S$1,Patrones!$B$57:$AZ$82,3,FALSE)) | Z6: 3 | AC6: =IF(AB6="","",AB6-HLOOKUP($S$1,Patrones!$B$57:$AZ$82,6,FALSE)) | AE6: 3 | AH6: =IF(AG6="","",AG6-HLOOKUP($S$1,Patrones!$B$57:$AZ$82,9,FALSE)) | AJ6: 02-0G-00002 | AK6: Conductímetro | AL6: Crítico | AM6: Área técnica | AN6: Mantenimiento e Ingeniería | AO6: 12
L7: Tipo | N7: =IF(N6="","",VLOOKUP($N$5,$AJ$3:$AO$2190,3,FALSE)) | R7: 5. 02-0G-00625 | U7: 4 | X7: =IF(W7="","",W7-HLOOKUP($S$1,Patrones!$B$57:$AZ$82,3,FALSE)) | Z7: 4 | AC7: =IF(AB7="","",AB7-HLOOKUP($S$1,Patrones!$B$57:$AZ$82,6,FALSE)) | AE7: 4 | AH7: =IF(AG7="","",AG7-HLOOKUP($S$1,Patrones!$B$57:$AZ$82,9,FALSE)) | AJ7: 02-0G-00003 | AK7: Conductímetro | AL7: Crítico | AM7: Área técnica | AN7: Mantenimiento e Ingeniería | AO7: 12
A8: Unidad | L8: Ubicación: | N8: =IF(N7="","",VLOOKUP($N$5,$AJ$3:$AO$2190,4,FALSE)) | R8: 6. 02-0G-00626 Ref | U8: 5 | X8: =IF(W8="","",W8-HLOOKUP($S$1,Patrones!$B$57:$AZ$82,3,FALSE)) | Z8: 5 | AC8: =IF(AB8="","",AB8-HLOOKUP($S$1,Patrones!$B$57:$AZ$82,6,FALSE)) | AE8: 5 | AH8: =IF(AG8="","",AG8-HLOOKUP($S$1,Patrones!$B$57:$AZ$82,9,FALSE)) | AJ8: 02-0G-00004 | AK8: Conductímetro | AL8: Crítico | AM8: Área técnica | AN8: Mantenimiento e Ingeniería | AO8: 12
A9: °C | F9: # Datos | G9: =N15*N16*2+4 -> 4 | L9: Departamento: | N9: =IF(N8="","",VLOOKUP($N$5,$AJ$3:$AO$2190,5,FALSE)) | R9: 7. 02-0G-00626 Ref 2 | V9: =AVERAGE(V4:V8) -> #DIV/0! | AJ9: 02-0G-00005 | AK9: Termohigrómetro | AL9: Crítico | AM9: Área técnica del liofilizador | AN9: Mantenimiento e Ingeniería | AO9: 6
A10: °F | F10: Datos reg | G10: =COUNT(V4:W8,AA4:AB8,AF4:AG8,V12:W16,AA12:AB16,R23:S24) -> 0 | L10: Frecuencia | N10: =IF(N9="","",VLOOKUP($N$5,$AJ$3:$AO$2190,6,FALSE)) | R10: 8. 02-0G-00626 (2) | W10: =R27 -> 0 | X10: =$O$11 -> °C | AB10: =S27 -> 0 | AC10: =$O$11 -> °C | AJ10: 02-0G-00009 | AK10: Manómetro | AL10: Crítico | AM10: Área técnica de ductos de sistemas críticos | AN10: Mantenimiento e Ingeniería | AO10: 12
A11: °R | L11: Linferior | O11: °C | Q11: =IF(Q12=-1,0,Q12) -> -2 | R11: 9. 02-0G-00626 (4) | V11: IBC | W11: Patrón | X11: Patrón Corr | AA11: IBC | AB11: Patrón | AC11: Patrón Corr | AJ11: 02-0G-00010 | AK11: Manómetro | AL11: Crítico | AM11: Área técnica | AN11: Mantenimiento e Ingeniería | AO11: 12
L12: Lsuperior | O12: =O11 -> °C | Q12: =LEN(N13)-(LEN(INT(N13))+1) -> -2 | R12: 10. 02-02-05267 | U12: 1 | X12: =IF(W12="","",W12-HLOOKUP($S$1,Patrones!$B$57:$AZ$82,12,FALSE)) | Z12: 1 | AC12: =IF(AB12="","",AB12-HLOOKUP($S$1,Patrones!$B$57:$AZ$82,15,FALSE)) | AJ12: 02-0G-00011 | AK12: Manómetro | AL12: Crítico | AM12: Área técnica de ductos de sistemas críticos | AN12: Mantenimiento e Ingeniería | AO12: 12
A13: # Puntos | L13: Div. Minima | O13: =O11 -> °C | R13: 11. 02-0G-01781 | U13: 2 | X13: =IF(W13="","",W13-HLOOKUP($S$1,Patrones!$B$57:$AZ$82,12,FALSE)) | Z13: 2 | AC13: =IF(AB13="","",AB13-HLOOKUP($S$1,Patrones!$B$57:$AZ$82,15,FALSE)) | AJ13: 02-0G-00019 | AK13: Sensor de presión | AL13: Crítico | AM13: Área técnica del liofilizador | AN13: Mantenimiento e Ingeniería | AO13: 12
A14: 1 | L14: Factor resol | Q14: =LEN(MID(W4,SEARCH(".",W4)+1,100)) -> #VALUE! | R14: 12. 02-02-05858 | U14: 3 | X14: =IF(W14="","",W14-HLOOKUP($S$1,Patrones!$B$57:$AZ$82,12,FALSE)) | Z14: 3 | AC14: =IF(AB14="","",AB14-HLOOKUP($S$1,Patrones!$B$57:$AZ$82,15,FALSE)) | AJ14: 02-0G-00020 | AK14: Sensor de presión | AL14: Crítico | AM14: Área técnica del liofilizador | AN14: Mantenimiento e Ingeniería | AO14: 12
A15: 2 | L15: Puntos a calibrar | R15: 13. 02-02-03967 (1) | U15: 4 | X15: =IF(W15="","",W15-HLOOKUP($S$1,Patrones!$B$57:$AZ$82,12,FALSE)) | Z15: 4 | AC15: =IF(AB15="","",AB15-HLOOKUP($S$1,Patrones!$B$57:$AZ$82,15,FALSE)) | AJ15: 02-0G-00021 | AK15: Sensor de presión | AL15: Crítico | AM15: Área técnica del liofilizador | AN15: Mantenimiento e Ingeniería | AO15: 12
A16: 3 | L16: # Repeticiones | R16: 14. 02-02-03967 (2) | U16: 5 | X16: =IF(W16="","",W16-HLOOKUP($S$1,Patrones!$B$57:$AZ$82,12,FALSE)) | Z16: 5 | AC16: =IF(AB16="","",AB16-HLOOKUP($S$1,Patrones!$B$57:$AZ$82,15,FALSE)) | AJ16: 02-0G-00028 | AK16: Manómetro diferencial | AL16: Crítico | AM16: Azotea general 1 | AN16: Mantenimiento e Ingeniería | AO16: 12
A17: 4 | L17: Tolerancia | O17: =O11 -> °C | P17: =-N17 -> 0 | R17: 15. 02-02-04961 | AJ17: 02-0G-00029 | AK17: Manómetro diferencial | AL17: Crítico | AM17: Azotea general 1 | AN17: Mantenimiento e Ingeniería | AO17: 12
A18: 5 | P18: =-N18 -> 0 | R18: 16. 02-02-04962 | AJ18: 02-0G-00030 | AK18: Manómetro diferencial | AL18: Crítico | AM18: Azotea general 1 | AN18: Mantenimiento e Ingeniería | AO18: 12
AJ19: 02-0G-00033 | AK19: Manómetro diferencial | AL19: Crítico | AM19: Azotea general 1 | AN19: Mantenimiento e Ingeniería | AO19: 12
AJ20: 02-0G-00034 | AK20: Manómetro diferencial | AL20: Crítico | AM20: Azotea general 1 | AN20: Mantenimiento e Ingeniería | AO20: 12
R21: Condiciones ambientales | AJ21: 02-0G-00035 | AK21: Manómetro diferencial | AL21: Crítico | AM21: Azotea general 1 | AN21: Mantenimiento e Ingeniería | AO21: 12
R22: Iniciales | S22: Finales | AJ22: 02-0G-00036 | AK22: Manómetro diferencial | AL22: Crítico | AM22: Azotea general 1 | AN22: Mantenimiento e Ingeniería | AO22: 12
T23: °C | AJ23: 02-0G-00037 | AK23: Manómetro diferencial | AL23: Crítico | AM23: Azotea general 1 | AN23: Mantenimiento e Ingeniería | AO23: 12
N24: Num. decimales | T24: %HR | AJ24: 02-0G-00038 | AK24: Manómetro diferencial | AL24: Crítico | AM24: Azotea general 1 | AN24: Mantenimiento e Ingeniería | AO24: 12
P25: =-N25 -> 0 | AJ25: 02-0G-00039 | AK25: Manómetro diferencial | AL25: Crítico | AM25: Azotea general 1 | AN25: Mantenimiento e Ingeniería | AO25: 12
N26: 1er punto | O26: 2do punto | P26: 3er punto | R26: 4to punto | S26: 5to punto | AJ26: 02-0G-00040 | AK26: Manómetro diferencial | AL26: Crítico | AM26: Azotea general 1 | AN26: Mantenimiento e Ingeniería | AO26: 12
T27: °C | U27: =IF(G9>G10,"FALTAN DATOS PARA PRUEBA","LISTO, IMPRIMIR REPORTE") -> FALTAN DATOS PARA PRUEBA | AJ27: 02-0G-00041 | AK27: Manómetro diferencial | AL27: Crítico | AM27: Azotea general 1 | AN27: Mantenimiento e Ingeniería | AO27: 12
AJ28: 02-0G-00042 | AK28: Manómetro diferencial | AL28: Crítico | AM28: Azotea general 1 | AN28: Mantenimiento e Ingeniería | AO28: 12
N29: =COUNTA(N1,N3,O3,N4,N5,N6,N7,N8,N10,N11,N12,N13,N14,N15,#REF!) -> 6 | AJ29: 02-0G-00043 | AK29: Manómetro diferencial | AL29: Crítico | AM29: Azotea general 1 | AN29: Mantenimiento e Ingeniería | AO29: 12
A30: No | B30: Código | D30: Descripcioón | H30: Vigencia | I30: Reporte de calib | N30: Error (+) | O30: =IF(N15="Formula",N25,N18) -> 0 | T30: Punto | V30: Error 1 | W30: Error 2 | X30: Error 3 | Y30: Error 4 | AA30: Error 5 | AB30: u repetibilidad | AC30: u patrón | AD30: u resolución | AF30: u combinada | AG30: U expandida | AJ30: 02-0G-00044 | AK30: Sensor de temperatura | AL30: Crítico | AM30: Área técnica del liofilizador | AN30: Mantenimiento e Ingeniería | AO30: 12
A31: 1 | B31: 02-0G-00627 | D31: Sensor de temperatura RTD Patrón | H31: 46539 | I31: 0D-1226-1063 | N31: Error (-) | O31: =-O30 -> 0 | T31: =IF(N27="","",N27) | U31: 1 | V31: =V4-X4 -> #VALUE! | W31: =V5-X5 -> #VALUE! | X31: =V6-X6 -> #VALUE! | Y31: =V7-X7 -> #VALUE! | Z31: =AA31 -> #VALUE! | AA31: =V8-X8 -> #VALUE! | AB31: =IF($N$16=3,STDEV(V31:X31)/SQRT(COUNT(X4:X8)),STDEV(V31:AA31)/SQRT(COUNT(X4:X8))) -> #VALUE! | AC31: =IF(T31="","",HLOOKUP($S$1,Patrones!$B$57:$AZ$82,4,FALSE)) | AD31: =($N$14*$N$13)/SQRT(12) -> 0 | AF31: =SQRT(SUMSQ(AB31,AC31,AD31)) -> #VALUE! | AG31: =AF31*2 -> #VALUE! | AJ31: 02-0G-00045 | AK31: Sensor de temperatura | AL31: Crítico | AM31: Área técnica del liofilizador | AN31: Mantenimiento e Ingeniería | AO31: 12
A32: 2 | B32: 02-02-03948 | D32: Termómetro digital | H32: 45168 | I32: 0D-0022-1362 | T32: =IF(O27="","",O27) | U32: 2 | V32: =AA4-AC4 -> #VALUE! | W32: =AA5-AC5 -> #VALUE! | X32: =AA6-AC6 -> #VALUE! | Y32: =AA7-AC7 -> #VALUE! | Z32: =AA32 -> #VALUE! | AA32: =AA8-AC8 -> #VALUE! | AB32: =IF($N$16=3,STDEV(V32:X32)/SQRT(COUNT(AC4:AC8)),STDEV(V32:AA32)/SQRT(COUNT(AC4:AC8))) -> #VALUE! | AC32: =IF(T32="","",HLOOKUP($S$1,Patrones!$B$57:$AZ$82,7,FALSE)) | AD32: =($N$14*$N$13)/SQRT(12) -> 0 | AF32: =SQRT(SUMSQ(AB32,AC32,AD32)) -> #VALUE! | AG32: =AF32*2 -> #VALUE! | AJ32: 02-0G-00046 | AK32: Sensor de temperatura | AL32: Crítico | AM32: Área técnica del liofilizador | AN32: Mantenimiento e Ingeniería | AO32: 12
A33: 3 | B33: 02-0G-01389 | D33: Sensor de temperatura RTD Patrón | H33: 45809 | I33: OD-1224-0873 | T33: =IF(P27="","",P27) | U33: 3 | V33: =AF4-AH4 -> #VALUE! | W33: =AF6-AH6 -> #VALUE! | X33: =AF7-AH7 -> #VALUE! | Y33: =AF8-AH8 -> #VALUE! | Z33: =AA33 -> #VALUE! | AA33: =AF8-AH8 -> #VALUE! | AB33: =IF($N$16=3,STDEV(V33:X33)/SQRT(COUNT(AH4:AH8)),STDEV(V33:AA33)/SQRT(COUNT(AH4:AH8))) -> #VALUE! | AC33: =IF(T33="","",HLOOKUP($S$1,Patrones!$B$57:$AZ$82,10,FALSE)) | AD33: =($N$14*$N$13)/SQRT(12) -> 0 | AF33: =SQRT(SUMSQ(AB33,AC33,AD33)) -> #VALUE! | AG33: =AF33*2 -> #VALUE! | AJ33: 02-0G-00047 | AK33: Sensor de temperatura | AL33: Crítico | AM33: Área técnica del liofilizador | AN33: Mantenimiento e Ingeniería | AO33: 12
A34: 4 | B34: 02-0G-00955 | D34: Sensor de temperatura | H34: 46235 | I34: 0D-1225-0052 | T34: =IF(R27="","",R27) | U34: 4 | V34: =V12-X12 -> #VALUE! | W34: =V13-X13 -> #VALUE! | X34: =V14-X14 -> #VALUE! | Y34: =V15-X15 -> #VALUE! | Z34: =AA34 -> #VALUE! | AA34: =V16-X16 -> #VALUE! | AB34: =IF($N$16=3,STDEV(V34:X34)/SQRT(COUNT(X12:X16)),STDEV(V34:AA34)/SQRT(COUNT(X12:X16))) -> #VALUE! | AC34: =IF(T34="","",HLOOKUP($S$1,Patrones!$B$57:$AZ$82,13,FALSE)) | AD34: =($N$14*$N$13)/SQRT(12) -> 0 | AF34: =SQRT(SUMSQ(AB34,AC34,AD34)) -> #VALUE! | AG34: =AF34*2 -> #VALUE! | AJ34: 02-0G-00048 | AK34: Sensor de temperatura | AL34: Crítico | AM34: Área técnica del liofilizador | AN34: Mantenimiento e Ingeniería | AO34: 12
A35: 5 | B35: 02-0G-00625 | D35: Sensor de temperatura RTD Patrón | H35: 46204 | I35: 0D-1225-0465 | T35: =IF(S27="","",S27) | U35: 5 | V35: =AA12-AC12 -> #VALUE! | W35: =AA13-AC13 -> #VALUE! | X35: =AA14-AC14 -> #VALUE! | Y35: =AA15-AC15 -> #VALUE! | Z35: =AA35 -> #VALUE! | AA35: =AA16-AC16 -> #VALUE! | AB35: =IF($N$16=3,STDEV(V35:X35)/SQRT(COUNT(AC12:AC16)),STDEV(V35:AA35)/SQRT(COUNT(AC12:AC16))) -> #VALUE! | AC35: =IF(T35="","",HLOOKUP($S$1,Patrones!$B$57:$AZ$82,16,FALSE)) | AD35: =($N$14*$N$13)/SQRT(12) -> 0 | AF35: =SQRT(SUMSQ(AB35,AC35,AD35)) -> #VALUE! | AG35: =AF35*2 -> #VALUE! | AJ35: 02-0G-00049 | AK35: Sensor de temperatura | AL35: Crítico | AM35: Área técnica del liofilizador | AN35: Mantenimiento e Ingeniería | AO35: 12
A36: 6 | B36: 02-0G-00626 REF 1 | D36: Referencia baja temperatura | H36: 46174 | I36: 0D-1225-0583 | AJ36: 02-0G-00050 | AK36: Sensor de temperatura | AL36: Crítico | AM36: Área técnica del liofilizador | AN36: Mantenimiento e Ingeniería | AO36: 12
A37: 7 | B37: 02-0G-00626 REF 2 | D37: Referencia baja temperatura | H37: 46174 | I37: 0D-1225-0583 | AJ37: 02-0G-00053 | AK37: Transmisor de temperatura | AL37: Crítico | AM37: Área técnica | AN37: Mantenimiento e Ingeniería | AO37: 12
A38: 8 | B38: 02-0G-00626 (2) | D38: Referencia baja temperatura | H38: 46174 | I38: 0D-1225-0583 | AJ38: 02-0G-00054 | AK38: Transmisor de temperatura | AL38: Crítico | AM38: Área técnica | AN38: Mantenimiento e Ingeniería | AO38: 12
A39: 9 | B39: 02-0G-00626 (4) | D39: Referencia baja temperatura | H39: 46174 | I39: 0D-1225-0583 | AJ39: 02-0G-00055 | AK39: Transmisor de temperatura | AL39: Crítico | AM39: Área técnica | AN39: Mantenimiento e Ingeniería | AO39: 12
A40: 10 | B40: 02-02-05267 | D40: Sensor de temperatura | H40: 44650 | I40: 0D-0021-0714 | AJ40: 02-0G-00056 | AK40: Transmisor de temperatura | AL40: Crítico | AM40: Área técnica | AN40: Mantenimiento e Ingeniería | AO40: 12
...

Sheet Reporte (2)
D2: Gestion de calibracion
D4: Reporte de Calibración | J4: Código: | L4: =CONCATENATE("0D-12",TEXT('datos crudos'!N3,"00"),"-",TEXT('datos crudos'!O3,"0000"),":002") -> 0D-1226-0000:002
J5: Fecha de calibración: | L5: ='datos crudos'!N1 -> 0
B6: Probiomed S.A. de C.V.
B7: San Esteban 88 Col. Santo Tomás, Alcaldía Azcapotzalco Ciudad de México C.P. 02020
C9: 1 Datos del instrumento bajo calibración
B11: Código: | F11: ='datos crudos'!N5 -> 0
B12: Descripción: | F12: ='datos crudos'!N6 | I12: =IF(L22<L23,"NO IMPRIMIR, LA FECHA DE CALIBRACIÓN DEL PATRÓN ESTA VENCIDA",) -> #N/A
B13: Criticidad: | F13: ='datos crudos'!N7
B14: Intervalo de medición: | F14: =CONCATENATE('datos crudos'!N11," ","a"," ",'datos crudos'!N12,'datos crudos'!O13) -> a °C
B15: Ubicación: | F15: ='datos crudos'!N8
B16: Departamento: | F16: ='datos crudos'!N9
B17: Tolerancia: | F17: ='datos crudos'!N17 -> 0 | G17: ='datos crudos'!O12 -> °C
B19: 2 Datos del instrumento de referencia
B21: Código: | F21: =VLOOKUP('datos crudos'!$S$1,'datos crudos'!$A$31:$J$53,2,FALSE) -> #N/A | K21: Informe de calibración: | L21: =VLOOKUP('datos crudos'!$S$1,'datos crudos'!$A$31:$J$53,9,FALSE) -> #N/A
B22: Descripción: | F22: =VLOOKUP('datos crudos'!$S$1,'datos crudos'!$A$31:$J$53,4,FALSE) -> #N/A | K22: Vigencia: | L22: =VLOOKUP('datos crudos'!$S$1,'datos crudos'!$A$31:$J$53,8,FALSE) -> #N/A
L23: =TODAY() -> 46253
B25: 3 Condiciones ambientales
B27: Temperatura ambiente: | G27: =AVERAGE('datos crudos'!R23:S23) -> #DIV/0! | H27: °C | I27: Humedad Relativa: | K27: =CONCATENATE(AVERAGE('datos crudos'!R24:S24),"% HR") -> #DIV/0!
B30: 4 Tabla de resultados
E32: Puntos | G32: Lectura IBC | H32: Lectura Patrón | J32: Error de medición | K32: Incertidumbre
G33: ='datos crudos'!O11 -> °C | H33: =G33 -> °C | J33: =G33 -> °C | K33: =G33 -> °C
E34: 1 | G34: =FIXED(AVERAGE('datos crudos'!V4:V8),'datos crudos'!$O$24,TRUE) -> #DIV/0! | H34: =FIXED(AVERAGE('datos crudos'!X4:X8),'datos crudos'!$O$24,TRUE) -> #DIV/0! | I34: =AVERAGE(#REF!,#REF!,#REF!,#REF!) -> #REF! | J34: =FIXED(G34-H34,'datos crudos'!$O$24,TRUE) -> #DIV/0! | K34: =FIXED('datos crudos'!AG31,'datos crudos'!$O$24,TRUE) -> #VALUE! | L34: =ABS(J34) -> #DIV/0!
E35: 2 | G35: =FIXED(AVERAGE('datos crudos'!AA4:AA8),'datos crudos'!$O$24,TRUE) -> #DIV/0! | H35: =FIXED(AVERAGE('datos crudos'!AC4:AC8),'datos crudos'!$O$24,TRUE) -> #DIV/0! | I35: =AVERAGE(#REF!,#REF!,#REF!,#REF!) -> #REF! | J35: =FIXED(G35-H35,'datos crudos'!$O$24,TRUE) -> #DIV/0! | K35: =FIXED('datos crudos'!AG32,'datos crudos'!$O$24,TRUE) -> #VALUE! | L35: =ABS(J35) -> #DIV/0!
E36: 3 | G36: =FIXED(AVERAGE('datos crudos'!AF4:AF8),'datos crudos'!$O$24,TRUE) -> #DIV/0! | H36: =FIXED(AVERAGE('datos crudos'!AH4:AH8),'datos crudos'!$O$24,TRUE) -> #DIV/0! | I36: =AVERAGE(#REF!,#REF!,#REF!,#REF!) -> #REF! | J36: =FIXED(G36-H36,'datos crudos'!$O$24,TRUE) -> #DIV/0! | K36: =FIXED('datos crudos'!AG33,'datos crudos'!$O$24,TRUE) -> #VALUE! | L36: =ABS(J36) -> #DIV/0!
E37: 4 | G37: =FIXED(AVERAGE('datos crudos'!V12:V16),'datos crudos'!O24,TRUE) -> #DIV/0! | H37: =FIXED(AVERAGE('datos crudos'!X12:X16),'datos crudos'!$O$24,TRUE) -> #DIV/0! | I37: =AVERAGE(#REF!,#REF!,#REF!,#REF!) -> #REF! | J37: =FIXED(G37-H37,'datos crudos'!$O$24,TRUE) -> #DIV/0! | K37: =FIXED('datos crudos'!AG34,'datos crudos'!$O$24,TRUE) -> #VALUE! | L37: =ABS(J37) -> #DIV/0!
E38: 5 | G38: =FIXED(AVERAGE('datos crudos'!AA12:AA16),'datos crudos'!O24,TRUE) -> #DIV/0! | H38: =FIXED(AVERAGE('datos crudos'!AC12:AC16),'datos crudos'!$O$24,TRUE) -> #DIV/0! | I38: =AVERAGE(#REF!,#REF!,#REF!,#REF!) -> #REF! | J38: =FIXED(G38-H38,'datos crudos'!$O$24,TRUE) -> #DIV/0! | K38: =FIXED('datos crudos'!AG35,'datos crudos'!$O$24,TRUE) -> #VALUE! | L38: =ABS(J38) -> #DIV/0!
L39: =IF('datos crudos'!N15=1,'Reporte (2)'!L34,IF('datos crudos'!N15=2,MAX('Reporte (2)'!L34:L35),IF('datos crudos'!N15=3,MAX('Reporte (2)'!L34:L36),IF('datos crudos'!N15=4,MAX('Reporte (2)'!L34:L37),MAX('Reporte (2)'!L34:L38))))) -> #DIV/0!
G41: =IF(AND('datos crudos'!N26=3),ABS(MAX('Reporte (2)'!L34:L36)),IF(AND('datos crudos'!N26=5),ABS(MAX('Reporte (2)'!L34:L38)),IF(AND('datos crudos'!N26=8),ABS(MAX(L34:L38))))) -> FALSE
E42: Dictamen: | G42: =IF(L39<=F17,"CUMPLE","NO CUMPLE") -> #DIV/0! | J42: Próxima Calibración: | K42: =IF(G42="No cumple","RECHAZADO",IF(G42="cumple",EDATE('datos crudos'!N1,'datos crudos'!N10))) -> #DIV/0!
C45: 5 Observaciones
B47: ÷ | C47: =IF('datos crudos'!N15=1,"La calibración se realizó de acuerdo al procedimiento SOP-000042885, Calibración general de instrumentos de medición","÷ La calibración se realizó de acuerdo al procedimiento SOP-000026896, Calibración de instrumentos medidores de temperatura") -> ÷ La calibración se realizó de acuerdo al procedimiento SOP-000026896, Calibración de instrumentos medidores de temperatura
B48: ÷ | C48: La incertidumbre de medición se calculó en base a la guía para estimar la incertidumbre, CENAM 2004 para un factor de cobertura k=2 (nivel de confianza 95.45 %)
B49: ÷ | C49: La calibración se realizó por comparación directa con un instrumento trazable al Sistema Internacional de unidades
C53: 6 Autorizaciones
C54: Actividad | D54: Nombre | H54: Puesto | K54: Firma | L54: Fecha
C55: Realizó: | D55: ='datos crudos'!N4 -> 0 | H55: =VLOOKUP('datos crudos'!N4,'datos crudos'!A2:I6,6,FALSE) -> #N/A
C56: Revisó: | D56: ='datos crudos'!A6 -> Ricardo Israel Padua Téllez | H56: ='datos crudos'!F6 -> Supervisor de Calibración

Sheet Patrones
A1: =TODAY() -> 46253
A2: ='datos crudos'!$O$12 -> °C
A3: Error de medición | B3: 0 | C3: 1 | D3: 2 | E3: 3 | F3: 4 | G3: 5 | H3: 6 | I3: 7 | J3: 8 | K3: 9 | L3: 10 | M3: 11 | N3: 12 | O3: 13 | P3: 14 | Q3: 15 | R3: 16 | S3: 17 | T3: 18 | U3: 19 | V3: 20 | W3: 21 | X3: 22 | Y3: 23 | Z3: 24 | AA3: 25 | AB3: 26 | AC3: 27 | AD3: 28 | AE3: 29 | AF3: 30 | AG3: 31 | AH3: 32 | AI3: 33 | AJ3: 34 | AK3: 35 | AL3: 33 | AM3: 34 | AN3: 35 | AO3: 36 | AP3: 37 | AQ3: 38 | AR3: 39 | AS3: 40 | AT3: 41 | AU3: 42 | AV3: 43 | AW3: 44 | AX3: 45 | AY3: 46 | AZ3: 47 | BA3: 36
A4: Reporte | B4: 0D-1226-1063 | E4: 0D-0022-1362 | H4: OD-1224-0873 | K4: 0D-1225-0052 | N4: 0D-1225-0465 | Q4: 0D-0021-0714 | T4: 0D-1225-1540 | W4: 0D-0019-1072 | Z4: 0D-1225-0583 | AC4: 0D-1225-0583 | AF4: 0D-1225-0583 | AI4: 0D-1225-0583 | AL4: 0D-0024-1913 | AO4: 0D-1225-1156 | AR4: 0D-1225-1156 | AU4: 0D-0022-2106 | AX4: 0D-0022-2107
A5: Vigencia | B5: 46539 | E5: 45169 | H5: 45809 | K5: 46235 | N5: 46204 | Q5: 44621 | T5: 46327 | W5: 44105 | Z5: 46174 | AC5: 46174 | AF5: 46174 | AI5: 46174 | AL5: 45931 | AO5: 46235 | AR5: 46235 | AU5: 45291 | AX5: 45291
A6: Código | C6: 02-0G-00627 | F6: 02-02-03948 | I6: 02-0G-01389 | L6: 02-0G-00955 | O6: 02-0G-00625 | R6: 02-02-05267 | U6: 02-0G-01781 | W6: 02-02-02482 | X6: 1000 | Y6: bar | AA6: 02-0G-00626 | AB6: Ref. 1 | AD6: 02-0G-00626 | AE6: REF 2 | AG6: 02-0G-00626 | AH6: pozo 2 | AJ6: 02-0G-00626 | AK6: pozo 4 | AM6: 02-02-05858 | AP6: 02-02-03967 (1) | AS6: 02-02-03967 (2) | AV6: 02-02-04961 | AY6: 02-02-04962
B7: Temperatura | C7: Error | D7: Incertidumbre | E7: Temperatura | F7: Error | G7: Incertidumbre | H7: Temperatura | I7: Error | J7: Incertidumbre | K7: Temperatura | L7: Error | M7: Incertidumbre | N7: Temperatura | O7: Error | P7: Incertidumbre | Q7: Temperatura | R7: Error | S7: Incertidumbre | T7: Temperatura | U7: Error | V7: Incertidumbre | W7: Presion | X7: Error | Y7: Incertidumbre | Z7: Temperatura | AA7: Error | AB7: Incertidumbre | AC7: Temperatura | AD7: Error | AE7: Incertidumbre | AF7: Temperatura | AG7: Error | AH7: Incertidumbre | AI7: Temperatura | AJ7: Error | AK7: Incertidumbre | AL7: Temperatura | AM7: Error | AN7: Incertidumbre | AO7: Temperatura | AP7: Error | AQ7: Incertidumbre | AR7: Temperatura | AS7: Error | AT7: Incertidumbre | AU7: Temperatura | AV7: Error | AW7: Incertidumbre
B8: -80.066 | C8: -0.113 | D8: 0.036 | E8: -80.1 | F8: -0.122 | G8: 0.04 | H8: -80.74 | I8: 0.008 | J8: 0.067 | K8: -24.9 | L8: 0.1 | M8: =0.27*2 -> 0.54 | N8: -81.462 | O8: 0.0258 | P8: 0.018 | Q8: -80.15 | R8: -0.166 | S8: 0.056 | T8: -81.8 | U8: -0.054 | V8: =0.068*2 -> 0.136 | W8: 50.6351 | X8: 0.613 | Y8: 0.0502 | Z8: -24.99 | AA8: 0 | AB8: 0.13 | AC8: -25.03 | AD8: 0.04 | AE8: 0.13 | AF8: -25.04 | AG8: 0.05 | AH8: 0.13 | AI8: -25.04 | AJ8: 0.04 | AK8: 0.13 | AL8: -89.8 | AM8: 0.164 | AN8: 0.146 | AO8: -25.1 | AP8: -0.05 | AQ8: 0.54 | AR8: -25 | AS8: 0.05 | AT8: 0.54 | AU8: 20.52 | AV8: -0.01 | AW8: 0.1 | AX8: 20.56 | AY8: 0.02 | AZ8: 0.1 | BA8: 1
B9: -60.009 | C9: -0.068 | D9: 0.036 | E9: -40.1 | F9: -0.099 | G9: 0.0305 | H9: -49.747 | I9: -0.003 | J9: 0.067 | K9: -9.8 | L9: 0.2 | M9: 0.6 | N9: -30.184 | O9: -0.0083 | P9: 0.018 | Q9: -40.11 | R9: -0.092 | S9: 0.022 | T9: -49.9 | U9: -0.088 | V9: =0.068*2 -> 0.136 | W9: 150.5915 | X9: 0.5867 | Y9: 0.0853 | Z9: -19.99 | AA9: 0 | AB9: 0.13 | AC9: -20.03 | AD9: 0.04 | AE9: 0.13 | AF9: -20.03 | AG9: 0.03 | AH9: 0.13 | AI9: -20.01 | AJ9: 0.02 | AK9: 0.13 | AL9: -59.9 | AM9: 0.057 | AN9: 0.153 | AO9: -10.1 | AP9: -0.08 | AQ9: 0.54 | AR9: -10.2 | AS9: -0.18 | AT9: 0.54 | AU9: 36.63 | AV9: 0.01 | AW9: 0.1 | AX9: 36.67 | AY9: 0.07 | AZ9: 0.1 | BA9: 2 | BF9: 0.0346 | BG9: =BF9/2 -> 0.0173
B10: -40.043 | C10: -0.098 | D10: 0.036 | E10: -20.2 | F10: -0.16 | G10: 0.03 | H10: -24.684 | I10: -0.011 | J10: 0.071 | K10: 0.14 | L10: 0.14 | M10: =0.27*2 -> 0.54 | N10: -20.144 | O10: -0.0086 | P10: 0.018 | Q10: -19.94 | R10: 0.062 | S10: 0.022 | T10: -30 | U10: -0.106 | V10: =0.068*2 -> 0.136 | W10: 250.63 | X10: 0.6321 | Y10: 0.1047 | Z10: -0.01 | AA10: 0 | AB10: 0.13 | AC10: -0.02 | AD10: 0 | AE10: 0.13 | AF10: 0 | AG10: 0.02 | AH10: 0.13 | AI10: 0.03 | AJ10: 0.04 | AK10: 0.13 | AL10: -39.9 | AM10: 0.084 | AN10: 0.153 | AO10: -0.2 | AP10: -0.18 | AQ10: 0.54 | AR10: -0.2 | AS10: -0.18 | AT10: 0.54 | AU10: 40.33 | AV10: 0.03 | AW10: 0.1 | BA10: 3
B11: -20.036 | C11: -0.079 | D11: 0.036 | E11: -0.2 | F11: -0.136 | G11: 0.0295 | H11: 0.353 | I11: 0.006 | J11: 0.067 | K11: 14.9 | L11: -0.1 | M11: =0.27*2 -> 0.54 | N11: -0.049 | O11: -0.0198 | P11: 0.018 | Q11: 0.16 | R11: 0.237 | S11: 0.016 | T11: -9.3 | U11: 0.126 | V11: =0.068*2 -> 0.136 | W11: 350.61 | X11: 0.628 | Y11: 0.1265 | Z11: 4.99 | AA11: 0 | AB11: 0.13 | AC11: 4.97 | AD11: 0.01 | AE11: 0.13 | AF11: 4.98 | AG11: 0.01 | AH11: 0.13 | AI11: 4.99 | AJ11: 0 | AK11: 0.13 | AL11: -0.1 | AM11: -0.061 | AN11: 0.146 | AO11: 14.9 | AP11: -0.09 | AQ11: 0.54 | AR11: 14.8 | AS11: -0.19 | AT11: 0.54 | BA11: 4
B12: -10.048 | C12: -0.085 | D12: 0.036 | E12: 36.6 | F12: -0.063 | G12: 0.0295 | H12: 25.033 | I12: -0.004 | J12: 0.067 | K12: 30 | L12: 0 | M12: =0.27*2 -> 0.54 | N12: 24.979 | O12: -0.0236 | P12: 0.018 | Q12: 25.17 | R12: 0.329 | S12: 0.016 | T12: -0.6 | U12: -0.222 | V12: =0.068*2 -> 0.136 | W12: 450.6 | X12: 0.6362 | Y12: 0.1705 | Z12: 9.99 | AA12: 0 | AB12: 0.13 | AC12: 10 | AD12: 0.01 | AE12: 0.13 | AF12: 9.99 | AG12: 0 | AH12: 0.13 | AI12: 10 | AJ12: 0.01 | AK12: 0.13 | AL12: 9.9 | AM12: -0.087 | AN12: 0.146 | AO12: 29.9 | AP12: -0.09 | AQ12: 0.54 | AR12: 29.9 | AS12: -0.09 | AT12: 0.54 | BA12: 5
B13: -0.064 | C13: -0.069 | D13: 0.036 | E13: 69.7 | F13: -0.266 | G13: 0.03 | H13: 50.023 | I13: -0.026 | J13: 0.067 | K13: 49.8 | L13: -0.2 | M13: =0.27*2 -> 0.54 | N13: 49.983 | O13: -0.0417 | P13: 0.018 | Q13: 50.27 | R13: 0.256 | S13: 0.016 | T13: 10.2 | U13: -0.047 | V13: =0.068*2 -> 0.136 | Z13: 19.98 | AA13: 0 | AB13: 0.13 | AC13: 19.98 | AD13: 0 | AE13: 0.13 | AF13: 19.97 | AG13: 0.01 | AH13: 0.13 | AI13: 19.97 | AJ13: 0.01 | AK13: 0.13 | AL13: 19.9 | AM13: -0.017 | AN13: 0.146 | AO13: 50 | AP13: 0.01 | AQ13: 0.54 | AR13: 50 | AS13: 0.01 | AT13: 0.54 | BA13: 6
B14: 9.954 | C14: -0.058 | D14: 0.036 | E14: 120.2 | F14: 0.169 | G14: 0.03 | H14: 75.008 | I14: -0.02 | J14: 0.067 | K14: 75.3 | L14: 0.3 | M14: =0.27*2 -> 0.54 | N14: 120.496 | O14: 0.1045 | P14: 0.021 | Q14: 150.09 | R14: 0.159 | S14: 0.024 | T14: 30.9 | U14: -0.074 | V14: =0.068*2 -> 0.136 | Z14: 44.95 | AA14: 0 | AB14: 0.13 | AC14: 44.94 | AD14: 0.01 | AE14: 0.13 | AF14: 44.94 | AG14: 0.01 | AH14: 0.13 | AI14: 44.95 | AJ14: 0 | AK14: 0.13 | AL14: 40 | AM14: 0.067 | AN14: 0.153 | AO14: 75 | AP14: 0.08 | AQ14: 0.54 | AR14: 75 | AS14: 0.08 | AT14: 0.54 | BA14: 7
B15: 19.996 | C15: -0.019 | D15: 0.036 | E15: 200.3 | F15: 0.26 | G15: 0.03 | H15: 99.985 | I15: -0.035 | J15: 0.067 | K15: 99.5 | L15: -0.5 | M15: =0.27*2 -> 0.54 | N15: 239.192 | O15: 0.2591 | P15: 0.021 | Q15: 240.05 | R15: 0.024 | S15: 0.024 | T15: 50.7 | U15: 0.191 | V15: =0.068*2 -> 0.136 | Z15: 68.87 | AA15: 0 | AB15: 0.13 | AC15: 69.8 | AD15: 0.07 | AE15: 0.13 | AF15: 69.8 | AG15: 0.08 | AH15: 0.13 | AI15: 69.81 | AJ15: 0.06 | AK15: 0.13 | AL15: 100 | AM15: 0.083 | AN15: 0.153 | AO15: 99.96 | AP15: -0.03 | AQ15: 0.54 | AR15: 100 | AS15: 0.01 | AT15: 0.54 | BA15: 8
B16: 49.988 | C16: -0.04 | D16: 0.036 | E16: 250.3 | F16: 0.216 | G16: 0.031 | H16: 124.952 | I16: -0.035 | J16: 0.067 | K16: 119.4 | L16: -0.6 | M16: =0.27*2 -> 0.54 | N16: 398.867 | O16: 0.5363 | P16: 0.021 | Q16: 299.75 | R16: -0.0324 | S16: 0.024 | T16: 70.1 | U16: 0.126 | V16: =0.068*2 -> 0.136 | Z16: 99.9 | AA16: 0 | AB16: 0.13 | AC16: 99.91 | AD16: 0 | AE16: 0.13 | AF16: 99.91 | AG16: 0.01 | AH16: 0.13 | AI16: 99.92 | AJ16: 0.01 | AK16: 0.13 | AL16: 119.9 | AM16: -0.029 | AN16: 0.146 | AO16: 119.9 | AP16: -0.09 | AQ16: 0.54 | AR16: 119.9 | AS16: -0.09 | AT16: 0.54 | BA16: 9
B17: 80.01 | C17: -0.003 | D17: 0.036 | E17: 270.4 | F17: 0.288 | G17: 0.031 | H17: 149.936 | I17: -0.033 | J17: 0.067 | K17: 139.2 | L17: -0.8 | M17: =0.27*2 -> 0.54 | Q17: 399.16 | R17: -1.025 | S17: 0.062 | T17: 100.1 | U17: 0.19 | V17: =0.071*2 -> 0.142 | Z17: 120.89 | AA17: 0 | AB17: 0.13 | AC17: 120.9 | AD17: 0 | AE17: 0.13 | AF17: 120.91 | AG17: 0.01 | AH17: 0.13 | AI17: 120.9 | AJ17: 0.01 | AK17: 0.13 | AL17: 199.9 | AM17: -0.118 | AN17: 0.146 | AO17: 139.8 | AP17: -0.2 | AQ17: 0.54 | AR17: 139.9 | AS17: -0.1 | AT17: 0.54 | BA17: 10
B18: 99.996 | C18: 0.187 | D18: 0.042 | H18: 199.932 | I18: -0.023 | J18: 0.067 | Z18: 139.87 | AA18: 0 | AB18: 0.13 | AC18: 139.87 | AD18: 0 | AE18: 0.13 | AF18: 139.87 | AG18: 0 | AH18: 0.13 | AI18: 139.88 | AJ18: 0 | AK18: 0.13 | AL18: 250 | AM18: 0.078 | AN18: 0.146 | BA18: 11
B19: 120.033 | C19: 0.21 | D19: 0.042 | H19: 249.932 | I19: -0.019 | J19: 0.067 | AL19: 270 | AM19: 0.064 | AN19: 0.153 | BA19: 12
B20: 149.391 | C20: 0.088 | D20: 0.042 | H20: 299.95 | I20: -0.021 | J20: 0.11 | AL20: 300.2 | AM20: 0.153 | AN20: 0.153 | BA20: 13
B21: 199.305 | C21: 0.239 | D21: 0.042 | H21: 349.95 | I21: 0.011 | J21: 0.11 | BA21: 14
B22: 249.587 | C22: 0.245 | D22: 0.042 | H22: 400 | I22: 0.032 | J22: 0.11 | BA22: 15
B23: 299.308 | C23: 0.275 | D23: 0.042 | BA23: 16
B24: 349.066 | C24: 0.325 | D24: 0.042 | BA24: 17
B25: 399.317 | C25: 0.547 | D25: 0.042 | BA25: 18
BA26: 19
BA27: 20
BA28: 21
BA29: 22
BA30: 23
BA31: 24
B32: Presion | C32: Error | D32: Incertidumbre | E32: Presion | F32: Error | G32: Incertidumbre | H32: Presion | I32: Error | J32: Incertidumbre | K32: Presion | L32: Error | M32: Incertidumbre | N32: Presion | O32: Error | P32: Incertidumbre | Q32: Presion | R32: Error | S32: Incertidumbre | T32: Presion | U32: Error | V32: Incertidumbre | W32: Presion | X32: Error | Y32: Incertidumbre | Z32: Presion | AA32: Error | AB32: Incertidumbre | AC32: Presion | AD32: Error | AE32: Incertidumbre | AF32: Presion | AG32: Error | AH32: Incertidumbre | AI32: Presion | AJ32: Error | AK32: Incertidumbre | AL32: Presion | AM32: Error | AN32: Incertidumbre | AO32: Presion | AP32: Error | AQ32: Incertidumbre | AR32: Presion | AS32: Error | AT32: Incertidumbre | AU32: Presion | AV32: Error | AW32: Incertidumbre | AX32: Presion | AY32: Error | AZ32: Incertidumbre
B33: =IF(B8="","",IF($A$2="°F",Patrones!B8*1.8+32,Patrones!B8)) -> -80.066 | C33: =IF(C8="","",IF($A$2="°F",Patrones!C8*1.8+32,Patrones!C8)) -> -0.113 | D33: =IF(D8="","",IF($A$2="°F",Patrones!D8*1.8+32,Patrones!D8)) -> 0.036 | E33: =IF(E8="","",IF($A$2="°F",Patrones!E8*1.8+32,Patrones!E8)) -> -80.1 | F33: =IF(F8="","",IF($A$2="°F",Patrones!F8*1.8+32,Patrones!F8)) -> -0.122 | G33: =IF(G8="","",IF($A$2="°F",Patrones!G8*1.8+32,Patrones!G8)) -> 0.04 | H33: =IF(H8="","",IF($A$2="°F",Patrones!H8*1.8+32,Patrones!H8)) -> -80.74 | I33: =IF(I8="","",IF($A$2="°F",Patrones!I8*1.8+32,Patrones!I8)) -> 0.008 | ... T33: =IF(T8="","",IF($A$2="°F",Patrones!T8*1.8+32,Patrones!T8)) -> -81.8 | U33: 0 | V33: =IF(V8="","",IF($A$2="°F",Patrones!V8*1.8+32,Patrones!V8)) -> 0.136 | W33: =IF(W8="","",(HLOOKUP($A$2,$C$1:$S$2,2,FALSE))*W8/(HLOOKUP(Y$6,$C$1:$S$2,2,FALSE))) -> #N/A | X33: =IF(X8="","",(HLOOKUP($A$2,$C$1:$S$2,2,FALSE))*X8/(HLOOKUP(Y$6,$C$1:$S$2,2,FALSE))) -> #N/A | Y33: =IF(Y8="","",(HLOOKUP($A$2,$C$1:$S$2,2,FALSE))*Y8/(HLOOKUP(Y$6,$C$1:$S$2,2,FALSE))) -> #N/A | Z33: =IF(Z8="","",IF($A$2="°F",Patrones!Z8*1.8+32,Patrones!Z8)) -> -24.99 | AA33: =IF(AA8="","",IF($A$2="°F",Patrones!AA8*1.8+32,Patrones!AA8)) -> 0 | AB33: =IF(AB8="","",IF($A$2="°F",Patrones!AB8*1.8+32,Patrones!AB8)) -> 0.13 | AC33: =IF(AC8="","",IF($A$2="°F",Patrones!AC8*1.8+32,Patrones!AC8)) -> -25.03 | AD33: =IF(AD8="","",IF($A$2="°F",Patrones!AD8*1.8+32,Patrones!AD8)) -> 0.04 | AE33: =IF(AE8="","",IF($A$2="°F",Patrones!AE8*1.8+32,Patrones!AE8)) -> 0.13 | AF33: =IF(AF8="","",IF($A$2="°F",Patrones!AF8*1.8+32,Patrones!AF8)) -> -25.04 | AG33: =IF(AG8="","",IF($A$2="°F",Patrones!AG8*1.8+32,Patrones!AG8)) -> 0.05 | ... AZ33: =IF(AZ8="","",IF($A$2="°F",Patrones!AZ8*1.8+32,Patrones!AZ8)) -> 0.1 | BA33: 1
B34: =IF(B9="","",IF($A$2="°F",Patrones!B9*1.8+32,Patrones!B9)) -> -60.009 | C34: =IF(C9="","",IF($A$2="°F",Patrones!C9*1.8+32,Patrones!C9)) -> -0.068 | D34: =IF(D9="","",IF($A$2="°F",Patrones!D9*1.8+32,Patrones!D9)) -> 0.036 | E34: =IF(E9="","",IF($A$2="°F",Patrones!E9*1.8+32,Patrones!E9)) -> -40.1 | F34: =IF(F9="","",IF($A$2="°F",Patrones!F9*1.8+32,Patrones!F9)) -> -0.099 | G34: =IF(G9="","",IF($A$2="°F",Patrones!G9*1.8+32,Patrones!G9)) -> 0.0305 | H34: =IF(H9="","",IF($A$2="°F",Patrones!H9*1.8+32,Patrones!H9)) -> -49.747 | I34: =IF(I9="","",IF($A$2="°F",Patrones!I9*1.8+32,Patrones!I9)) -> -0.003 | ... T34: =IF(T9="","",IF($A$2="°F",Patrones!T9*1.8+32,Patrones!T9)) -> -49.9 | U34: 0 | V34: =IF(V9="","",IF($A$2="°F",Patrones!V9*1.8+32,Patrones!V9)) -> 0.136 | W34: =IF(W9="","",(HLOOKUP($A$2,$C$1:$S$2,2,FALSE))*W9/(HLOOKUP(Y$6,$C$1:$S$2,2,FALSE))) -> #N/A | X34: =IF(X9="","",(HLOOKUP($A$2,$C$1:$S$2,2,FALSE))*X9/(HLOOKUP(Y$6,$C$1:$S$2,2,FALSE))) -> #N/A | Y34: =IF(Y9="","",(HLOOKUP($A$2,$C$1:$S$2,2,FALSE))*Y9/(HLOOKUP(Y$6,$C$1:$S$2,2,FALSE))) -> #N/A | Z34: =IF(Z9="","",IF($A$2="°F",Patrones!Z9*1.8+32,Patrones!Z9)) -> -19.99 | AA34: =IF(AA9="","",IF($A$2="°F",Patrones!AA9*1.8+32,Patrones!AA9)) -> 0 | AB34: =IF(AB9="","",IF($A$2="°F",Patrones!AB9*1.8+32,Patrones!AB9)) -> 0.13 | AC34: =IF(AC9="","",IF($A$2="°F",Patrones!AC9*1.8+32,Patrones!AC9)) -> -20.03 | AD34: =IF(AD9="","",IF($A$2="°F",Patrones!AD9*1.8+32,Patrones!AD9)) -> 0.04 | AE34: =IF(AE9="","",IF($A$2="°F",Patrones!AE9*1.8+32,Patrones!AE9)) -> 0.13 | AF34: =IF(AF9="","",IF($A$2="°F",Patrones!AF9*1.8+32,Patrones!AF9)) -> -20.03 | AG34: =IF(AG9="","",IF($A$2="°F",Patrones!AG9*1.8+32,Patrones!AG9)) -> 0.03 | ... AZ34: =IF(AZ9="","",IF($A$2="°F",Patrones!AZ9*1.8+32,Patrones!AZ9)) -> 0.1 | BA34: 2
B35: =IF(B10="","",IF($A$2="°F",Patrones!B10*1.8+32,Patrones!B10)) -> -40.043 | C35: =IF(C10="","",IF($A$2="°F",Patrones!C10*1.8+32,Patrones!C10)) -> -0.098 | D35: =IF(D10="","",IF($A$2="°F",Patrones!D10*1.8+32,Patrones!D10)) -> 0.036 | E35: =IF(E10="","",IF($A$2="°F",Patrones!E10*1.8+32,Patrones!E10)) -> -20.2 | F35: =IF(F10="","",IF($A$2="°F",Patrones!F10*1.8+32,Patrones!F10)) -> -0.16 | G35: =IF(G10="","",IF($A$2="°F",Patrones!G10*1.8+32,Patrones!G10)) -> 0.03 | H35: =IF(H10="","",IF($A$2="°F",Patrones!H10*1.8+32,Patrones!H10)) -> -24.684 | I35: =IF(I10="","",IF($A$2="°F",Patrones!I10*1.8+32,Patrones!I10)) -> -0.011 | ... T35: =IF(T10="","",IF($A$2="°F",Patrones!T10*1.8+32,Patrones!T10)) -> -30 | U35: 0 | V35: =IF(V10="","",IF($A$2="°F",Patrones!V10*1.8+32,Patrones!V10)) -> 0.136 | W35: =IF(W10="","",(HLOOKUP($A$2,$C$1:$S$2,2,FALSE))*W10/(HLOOKUP(Y$6,$C$1:$S$2,2,FALSE))) -> #N/A | X35: =IF(X10="","",(HLOOKUP($A$2,$C$1:$S$2,2,FALSE))*X10/(HLOOKUP(Y$6,$C$1:$S$2,2,FALSE))) -> #N/A | Y35: =IF(Y10="","",(HLOOKUP($A$2,$C$1:$S$2,2,FALSE))*Y10/(HLOOKUP(Y$6,$C$1:$S$2,2,FALSE))) -> #N/A | Z35: =IF(Z10="","",IF($A$2="°F",Patrones!Z10*1.8+32,Patrones!Z10)) -> -0.01 | AA35: =IF(AA10="","",IF($A$2="°F",Patrones!AA10*1.8+32,Patrones!AA10)) -> 0 | AB35: =IF(AB10="","",IF($A$2="°F",Patrones!AB10*1.8+32,Patrones!AB10)) -> 0.13 | AC35: =IF(AC10="","",IF($A$2="°F",Patrones!AC10*1.8+32,Patrones!AC10)) -> -0.02 | AD35: =IF(AD10="","",IF($A$2="°F",Patrones!AD10*1.8+32,Patrones!AD10)) -> 0 | AE35: =IF(AE10="","",IF($A$2="°F",Patrones!AE10*1.8+32,Patrones!AE10)) -> 0.13 | AF35: =IF(AF10="","",IF($A$2="°F",Patrones!AF10*1.8+32,Patrones!AF10)) -> 0 | AG35: =IF(AG10="","",IF($A$2="°F",Patrones!AG10*1.8+32,Patrones!AG10)) -> 0.02 | ... AZ35: =IF(AZ10="","",IF($A$2="°F",Patrones!AZ10*1.8+32,Patrones!AZ10)) | BA35: 3
B36: =IF(B11="","",IF($A$2="°F",Patrones!B11*1.8+32,Patrones!B11)) -> -20.036 | C36: =IF(C11="","",IF($A$2="°F",Patrones!C11*1.8+32,Patrones!C11)) -> -0.079 | D36: =IF(D11="","",IF($A$2="°F",Patrones!D11*1.8+32,Patrones!D11)) -> 0.036 | E36: =IF(E11="","",IF($A$2="°F",Patrones!E11*1.8+32,Patrones!E11)) -> -0.2 | F36: =IF(F11="","",IF($A$2="°F",Patrones!F11*1.8+32,Patrones!F11)) -> -0.136 | G36: =IF(G11="","",IF($A$2="°F",Patrones!G11*1.8+32,Patrones!G11)) -> 0.0295 | H36: =IF(H11="","",IF($A$2="°F",Patrones!H11*1.8+32,Patrones!H11)) -> 0.353 | I36: =IF(I11="","",IF($A$2="°F",Patrones!I11*1.8+32,Patrones!I11)) -> 0.006 | ... V36: =IF(V11="","",IF($A$2="°F",Patrones!V11*1.8+32,Patrones!V11)) -> 0.136 | W36: =IF(W11="","",(HLOOKUP($A$2,$C$1:$S$2,2,FALSE))*W11/(HLOOKUP(Y$6,$C$1:$S$2,2,FALSE))) -> #N/A | X36: =IF(X11="","",(HLOOKUP($A$2,$C$1:$S$2,2,FALSE))*X11/(HLOOKUP(Y$6,$C$1:$S$2,2,FALSE))) -> #N/A | Y36: =IF(Y11="","",(HLOOKUP($A$2,$C$1:$S$2,2,FALSE))*Y11/(HLOOKUP(Y$6,$C$1:$S$2,2,FALSE))) -> #N/A | Z36: =IF(Z11="","",IF($A$2="°F",Patrones!Z11*1.8+32,Patrones!Z11)) -> 4.99 | AA36: =IF(AA11="","",IF($A$2="°F",Patrones!AA11*1.8+32,Patrones!AA11)) -> 0 | AB36: =IF(AB11="","",IF($A$2="°F",Patrones!AB11*1.8+32,Patrones!AB11)) -> 0.13 | AC36: =IF(AC11="","",IF($A$2="°F",Patrones!AC11*1.8+32,Patrones!AC11)) -> 4.97 | AD36: =IF(AD11="","",IF($A$2="°F",Patrones!AD11*1.8+32,Patrones!AD11)) -> 0.01 | AE36: =IF(AE11="","",IF($A$2="°F",Patrones!AE11*1.8+32,Patrones!AE11)) -> 0.13 | AF36: =IF(AF11="","",IF($A$2="°F",Patrones!AF11*1.8+32,Patrones!AF11)) -> 4.98 | AG36: =IF(AG11="","",IF($A$2="°F",Patrones!AG11*1.8+32,Patrones!AG11)) -> 0.01 | ... AZ36: =IF(AZ11="","",IF($A$2="°F",Patrones!AZ11*1.8+32,Patrones!AZ11)) | BA36: 4
B37: =IF(B12="","",IF($A$2="°F",Patrones!B12*1.8+32,Patrones!B12)) -> -10.048 | C37: =IF(C12="","",IF($A$2="°F",Patrones!C12*1.8+32,Patrones!C12)) -> -0.085 | D37: =IF(D12="","",IF($A$2="°F",Patrones!D12*1.8+32,Patrones!D12)) -> 0.036 | E37: =IF(E12="","",IF($A$2="°F",Patrones!E12*1.8+32,Patrones!E12)) -> 36.6 | F37: =IF(F12="","",IF($A$2="°F",Patrones!F12*1.8+32,Patrones!F12)) -> -0.063 | G37: =IF(G12="","",IF($A$2="°F",Patrones!G12*1.8+32,Patrones!G12)) -> 0.0295 | H37: =IF(H12="","",IF($A$2="°F",Patrones!H12*1.8+32,Patrones!H12)) -> 25.033 | I37: =IF(I12="","",IF($A$2="°F",Patrones!I12*1.8+32,Patrones!I12)) -> -0.004 | ... V37: =IF(V12="","",IF($A$2="°F",Patrones!V12*1.8+32,Patrones!V12)) -> 0.136 | W37: =IF(W12="","",(HLOOKUP($A$2,$C$1:$S$2,2,FALSE))*W12/(HLOOKUP(Y$6,$C$1:$S$2,2,FALSE))) -> #N/A | X37: =IF(X12="","",(HLOOKUP($A$2,$C$1:$S$2,2,FALSE))*X12/(HLOOKUP(Y$6,$C$1:$S$2,2,FALSE))) -> #N/A | Y37: =IF(Y12="","",(HLOOKUP($A$2,$C$1:$S$2,2,FALSE))*Y12/(HLOOKUP(Y$6,$C$1:$S$2,2,FALSE))) -> #N/A | Z37: =IF(Z12="","",IF($A$2="°F",Patrones!Z12*1.8+32,Patrones!Z12)) -> 9.99 | AA37: =IF(AA12="","",IF($A$2="°F",Patrones!AA12*1.8+32,Patrones!AA12)) -> 0 | AB37: =IF(AB12="","",IF($A$2="°F",Patrones!AB12*1.8+32,Patrones!AB12)) -> 0.13 | AC37: =IF(AC12="","",IF($A$2="°F",Patrones!AC12*1.8+32,Patrones!AC12)) -> 10 | AD37: =IF(AD12="","",IF($A$2="°F",Patrones!AD12*1.8+32,Patrones!AD12)) -> 0.01 | AE37: =IF(AE12="","",IF($A$2="°F",Patrones!AE12*1.8+32,Patrones!AE12)) -> 0.13 | AF37: =IF(AF12="","",IF($A$2="°F",Patrones!AF12*1.8+32,Patrones!AF12)) -> 9.99 | AG37: =IF(AG12="","",IF($A$2="°F",Patrones!AG12*1.8+32,Patrones!AG12)) -> 0 | ... AZ37: =IF(AZ12="","",IF($A$2="°F",Patrones!AZ12*1.8+32,Patrones!AZ12)) | BA37: 5
B38: =IF(B13="","",IF($A$2="°F",Patrones!B13*1.8+32,Patrones!B13)) -> -0.064 | C38: =IF(C13="","",IF($A$2="°F",Patrones!C13*1.8+32,Patrones!C13)) -> -0.069 | D38: =IF(D13="","",IF($A$2="°F",Patrones!D13*1.8+32,Patrones!D13)) -> 0.036 | E38: =IF(E13="","",IF($A$2="°F",Patrones!E13*1.8+32,Patrones!E13)) -> 69.7 | F38: =IF(F13="","",IF($A$2="°F",Patrones!F13*1.8+32,Patrones!F13)) -> -0.266 | G38: =IF(G13="","",IF($A$2="°F",Patrones!G13*1.8+32,Patrones!G13)) -> 0.03 | H38: =IF(H13="","",IF($A$2="°F",Patrones!H13*1.8+32,Patrones!H13)) -> 50.023 | I38: =IF(I13="","",IF($A$2="°F",Patrones!I13*1.8+32,Patrones!I13)) -> -0.026 | ... V38: =IF(V13="","",IF($A$2="°F",Patrones!V13*1.8+32,Patrones!V13)) -> 0.136 | W38: =IF(W13="","",(HLOOKUP($A$2,$C$1:$S$2,2,FALSE))*W13/(HLOOKUP(Y$6,$C$1:$S$2,2,FALSE))) | X38: =IF(X13="","",(HLOOKUP($A$2,$C$1:$S$2,2,FALSE))*X13/(HLOOKUP(Y$6,$C$1:$S$2,2,FALSE))) | Y38: =IF(Y13="","",(HLOOKUP($A$2,$C$1:$S$2,2,FALSE))*Y13/(HLOOKUP(Y$6,$C$1:$S$2,2,FALSE))) | Z38: =IF(Z13="","",IF($A$2="°F",Patrones!Z13*1.8+32,Patrones!Z13)) -> 19.98 | AA38: =IF(AA13="","",IF($A$2="°F",Patrones!AA13*1.8+32,Patrones!AA13)) -> 0 | AB38: =IF(AB13="","",IF($A$2="°F",Patrones!AB13*1.8+32,Patrones!AB13)) -> 0.13 | AC38: =IF(AC13="","",IF($A$2="°F",Patrones!AC13*1.8+32,Patrones!AC13)) -> 19.98 | AD38: =IF(AD13="","",IF($A$2="°F",Patrones!AD13*1.8+32,Patrones!AD13)) -> 0 | AE38: =IF(AE13="","",IF($A$2="°F",Patrones!AE13*1.8+32,Patrones!AE13)) -> 0.13 | AF38: =IF(AF13="","",IF($A$2="°F",Patrones!AF13*1.8+32,Patrones!AF13)) -> 19.97 | AG38: =IF(AG13="","",IF($A$2="°F",Patrones!AG13*1.8+32,Patrones!AG13)) -> 0.01 | ... AZ38: =IF(AZ13="","",IF($A$2="°F",Patrones!AZ13*1.8+32,Patrones!AZ13)) | BA38: 6
B39: =IF(B14="","",IF($A$2="°F",Patrones!B14*1.8+32,Patrones!B14)) -> 9.954 | C39: =IF(C14="","",IF($A$2="°F",Patrones!C14*1.8+32,Patrones!C14)) -> -0.058 | D39: =IF(D14="","",IF($A$2="°F",Patrones!D14*1.8+32,Patrones!D14)) -> 0.036 | E39: =IF(E14="","",IF($A$2="°F",Patrones!E14*1.8+32,Patrones!E14)) -> 120.2 | F39: =IF(F14="","",IF($A$2="°F",Patrones!F14*1.8+32,Patrones!F14)) -> 0.169 | G39: =IF(G14="","",IF($A$2="°F",Patrones!G14*1.8+32,Patrones!G14)) -> 0.03 | H39: =IF(H14="","",IF($A$2="°F",Patrones!H14*1.8+32,Patrones!H14)) -> 75.008 | I39: =IF(I14="","",IF($A$2="°F",Patrones!I14*1.8+32,Patrones!I14)) -> -0.02 | ... V39: =IF(V14="","",IF($A$2="°F",Patrones!V14*1.8+32,Patrones!V14)) -> 0.136 | W39: =IF(W14="","",(HLOOKUP($A$2,$C$1:$S$2,2,FALSE))*W14/(HLOOKUP(Y$6,$C$1:$S$2,2,FALSE))) | X39: =IF(X14="","",(HLOOKUP($A$2,$C$1:$S$2,2,FALSE))*X14/(HLOOKUP(Y$6,$C$1:$S$2,2,FALSE))) | Y39: =IF(Y14="","",(HLOOKUP($A$2,$C$1:$S$2,2,FALSE))*Y14/(HLOOKUP(Y$6,$C$1:$S$2,2,FALSE))) | Z39: =IF(Z14="","",IF($A$2="°F",Patrones!Z14*1.8+32,Patrones!Z14)) -> 44.95 | AA39: =IF(AA14="","",IF($A$2="°F",Patrones!AA14*1.8+32,Patrones!AA14)) -> 0 | AB39: =IF(AB14="","",IF($A$2="°F",Patrones!AB14*1.8+32,Patrones!AB14)) -> 0.13 | AC39: =IF(AC14="","",IF($A$2="°F",Patrones!AC14*1.8+32,Patrones!AC14)) -> 44.94 | AD39: =IF(AD14="","",IF($A$2="°F",Patrones!AD14*1.8+32,Patrones!AD14)) -> 0.01 | AE39: =IF(AE14="","",IF($A$2="°F",Patrones!AE14*1.8+32,Patrones!AE14)) -> 0.13 | AF39: =IF(AF14="","",IF($A$2="°F",Patrones!AF14*1.8+32,Patrones!AF14)) -> 44.94 | AG39: =IF(AG14="","",IF($A$2="°F",Patrones!AG14*1.8+32,Patrones!AG14)) -> 0.01 | ... AZ39: =IF(AZ14="","",IF($A$2="°F",Patrones!AZ14*1.8+32,Patrones!AZ14)) | BA39: 7
B40: =IF(B15="","",IF($A$2="°F",Patrones!B15*1.8+32,Patrones!B15)) -> 19.996 | C40: =IF(C15="","",IF($A$2="°F",Patrones!C15*1.8+32,Patrones!C15)) -> -0.019 | D40: =IF(D15="","",IF($A$2="°F",Patrones!D15*1.8+32,Patrones!D15)) -> 0.036 | E40: =IF(E15="","",IF($A$2="°F",Patrones!E15*1.8+32,Patrones!E15)) -> 200.3 | F40: =IF(F15="","",IF($A$2="°F",Patrones!F15*1.8+32,Patrones!F15)) -> 0.26 | G40: =IF(G15="","",IF($A$2="°F",Patrones!G15*1.8+32,Patrones!G15)) -> 0.03 | H40: =IF(H15="","",IF($A$2="°F",Patrones!H15*1.8+32,Patrones!H15)) -> 99.985 | I40: =IF(I15="","",IF($A$2="°F",Patrones!I15*1.8+32,Patrones!I15)) -> -0.035 | ... V40: =IF(V15="","",IF($A$2="°F",Patrones!V15*1.8+32,Patrones!V15)) -> 0.136 | W40: =IF(W15="","",(HLOOKUP($A$2,$C$1:$S$2,2,FALSE))*W15/(HLOOKUP(Y$6,$C$1:$S$2,2,FALSE))) | X40: =IF(X15="","",(HLOOKUP($A$2,$C$1:$S$2,2,FALSE))*X15/(HLOOKUP(Y$6,$C$1:$S$2,2,FALSE))) | Y40: =IF(Y15="","",(HLOOKUP($A$2,$C$1:$S$2,2,FALSE))*Y15/(HLOOKUP(Y$6,$C$1:$S$2,2,FALSE))) | Z40: =IF(Z15="","",IF($A$2="°F",Patrones!Z15*1.8+32,Patrones!Z15)) -> 68.87 | AA40: =IF(AA15="","",IF($A$2="°F",Patrones!AA15*1.8+32,Patrones!AA15)) -> 0 | AB40: =IF(AB15="","",IF($A$2="°F",Patrones!AB15*1.8+32,Patrones!AB15)) -> 0.13 | AC40: =IF(AC15="","",IF($A$2="°F",Patrones!AC15*1.8+32,Patrones!AC15)) -> 69.8 | AD40: =IF(AD15="","",IF($A$2="°F",Patrones!AD15*1.8+32,Patrones!AD15)) -> 0.07 | AE40: =IF(AE15="","",IF($A$2="°F",Patrones!AE15*1.8+32,Patrones!AE15)) -> 0.13 | AF40: =IF(AF15="","",IF($A$2="°F",Patrones!AF15*1.8+32,Patrones!AF15)) -> 69.8 | AG40: =IF(AG15="","",IF($A$2="°F",Patrones!AG15*1.8+32,Patrones!AG15)) -> 0.08 | ... AZ40: =IF(AZ15="","",IF($A$2="°F",Patrones!AZ15*1.8+32,Patrones!AZ15)) | BA40: 8
...
